[2025-04-05T04:38:38.035+0000] {local_task_job_runner.py:120} INFO - ::group::Pre task execution logs
[2025-04-05T04:38:38.062+0000] {taskinstance.py:2076} INFO - Dependencies all met for dep_context=non-requeueable deps ti=<TaskInstance: e_commerce_dw_etl.load.transform_fact_race_results manual__2025-04-05T04:38:35.192923+00:00 [queued]>
[2025-04-05T04:38:38.069+0000] {taskinstance.py:2076} INFO - Dependencies all met for dep_context=requeueable deps ti=<TaskInstance: e_commerce_dw_etl.load.transform_fact_race_results manual__2025-04-05T04:38:35.192923+00:00 [queued]>
[2025-04-05T04:38:38.069+0000] {taskinstance.py:2306} INFO - Starting attempt 1 of 1
[2025-04-05T04:38:38.079+0000] {taskinstance.py:2330} INFO - Executing <Task(PythonOperator): load.transform_fact_race_results> on 2025-04-05 04:38:35.192923+00:00
[2025-04-05T04:38:38.087+0000] {standard_task_runner.py:90} INFO - Running: ['***', 'tasks', 'run', 'e_commerce_dw_etl', 'load.transform_fact_race_results', 'manual__2025-04-05T04:38:35.192923+00:00', '--job-id', '22', '--raw', '--subdir', 'DAGS_FOLDER/ETL_dag.py', '--cfg-path', '/tmp/tmpsgntx5nl']
[2025-04-05T04:38:38.089+0000] {standard_task_runner.py:91} INFO - Job 22: Subtask load.transform_fact_race_results
[2025-04-05T04:38:38.090+0000] {logging_mixin.py:188} WARNING - /home/***/.local/lib/python3.12/site-packages/***/task/task_runner/standard_task_runner.py:61 DeprecationWarning: This process (pid=873) is multi-threaded, use of fork() may lead to deadlocks in the child.
[2025-04-05T04:38:38.091+0000] {standard_task_runner.py:63} INFO - Started process 875 to run task
[2025-04-05T04:38:38.124+0000] {task_command.py:426} INFO - Running <TaskInstance: e_commerce_dw_etl.load.transform_fact_race_results manual__2025-04-05T04:38:35.192923+00:00 [running]> on host 0076f80062a6
[2025-04-05T04:38:38.188+0000] {taskinstance.py:2648} INFO - Exporting env vars: AIRFLOW_CTX_DAG_OWNER='***' AIRFLOW_CTX_DAG_ID='e_commerce_dw_etl' AIRFLOW_CTX_TASK_ID='load.transform_fact_race_results' AIRFLOW_CTX_EXECUTION_DATE='2025-04-05T04:38:35.192923+00:00' AIRFLOW_CTX_TRY_NUMBER='1' AIRFLOW_CTX_DAG_RUN_ID='manual__2025-04-05T04:38:35.192923+00:00'
[2025-04-05T04:38:38.190+0000] {taskinstance.py:430} INFO - ::endgroup::
[2025-04-05T04:38:38.305+0000] {logging_mixin.py:188} INFO - Các cột trong DataFrame sau khi merge:
[2025-04-05T04:38:38.306+0000] {logging_mixin.py:188} INFO - Index(['resultId', 'raceId', 'driverId', 'constructorId', 'number', 'grid',
       'position', 'positionText', 'positionOrder', 'points', 'laps', 'time_x',
       'milliseconds', 'fastestLap', 'rank', 'fastestLapTime',
       'fastestLapSpeed', 'statusId', 'year', 'round', 'circuitId', 'name',
       'date', 'time_y', 'url', 'fp1_date', 'fp1_time', 'fp2_date', 'fp2_time',
       'fp3_date', 'fp3_time', 'quali_date', 'quali_time', 'sprint_date',
       'sprint_time'],
      dtype='object')
[2025-04-05T04:38:38.390+0000] {taskinstance.py:441} INFO - ::group::Post task execution logs
[2025-04-05T04:38:38.398+0000] {taskinstance.py:2905} ERROR - Task failed with exception
Traceback (most recent call last):
  File "/home/airflow/.local/lib/python3.12/site-packages/airflow/models/taskinstance.py", line 465, in _execute_task
    result = _execute_callable(context=context, **execute_callable_kwargs)
             ^^^^^^^^^^^^^^^^^^^^^^^^^^^^^^^^^^^^^^^^^^^^^^^^^^^^^^^^^^^^^
  File "/home/airflow/.local/lib/python3.12/site-packages/airflow/models/taskinstance.py", line 432, in _execute_callable
    return execute_callable(context=context, **execute_callable_kwargs)
           ^^^^^^^^^^^^^^^^^^^^^^^^^^^^^^^^^^^^^^^^^^^^^^^^^^^^^^^^^^^^
  File "/home/airflow/.local/lib/python3.12/site-packages/airflow/models/baseoperator.py", line 401, in wrapper
    return func(self, *args, **kwargs)
           ^^^^^^^^^^^^^^^^^^^^^^^^^^^
  File "/home/airflow/.local/lib/python3.12/site-packages/airflow/operators/python.py", line 235, in execute
    return_value = self.execute_callable()
                   ^^^^^^^^^^^^^^^^^^^^^^^
  File "/home/airflow/.local/lib/python3.12/site-packages/airflow/operators/python.py", line 252, in execute_callable
    return self.python_callable(*self.op_args, **self.op_kwargs)
           ^^^^^^^^^^^^^^^^^^^^^^^^^^^^^^^^^^^^^^^^^^^^^^^^^^^^^
  File "/opt/airflow/dags/transform_fact_race_results.py", line 54, in transform_fact_race_results
    warehouse_operator.create_table(create_table_qr)
  File "/opt/airflow/dags/postgresql_operator.py", line 10, in create_table
    conn = pg_hook.get_conn()
           ^^^^^^^^^^^^^^^^^^
  File "/home/airflow/.local/lib/python3.12/site-packages/airflow/providers/postgres/hooks/postgres.py", line 145, in get_conn
    conn = deepcopy(self.connection or self.get_connection(conn_id))
                                       ^^^^^^^^^^^^^^^^^^^^^^^^^^^^
  File "/home/airflow/.local/lib/python3.12/site-packages/airflow/hooks/base.py", line 83, in get_connection
    conn = Connection.get_connection_from_secrets(conn_id)
           ^^^^^^^^^^^^^^^^^^^^^^^^^^^^^^^^^^^^^^^^^^^^^^^
  File "/home/airflow/.local/lib/python3.12/site-packages/airflow/models/connection.py", line 519, in get_connection_from_secrets
    raise AirflowNotFoundException(f"The conn_id `{conn_id}` isn't defined")
airflow.exceptions.AirflowNotFoundException: The conn_id `postgres_default` isn't defined
[2025-04-05T04:38:38.407+0000] {taskinstance.py:1206} INFO - Marking task as FAILED. dag_id=e_commerce_dw_etl, task_id=load.transform_fact_race_results, run_id=manual__2025-04-05T04:38:35.192923+00:00, execution_date=20250405T043835, start_date=20250405T043838, end_date=20250405T043838
[2025-04-05T04:38:38.416+0000] {standard_task_runner.py:110} ERROR - Failed to execute job 22 for task load.transform_fact_race_results (The conn_id `postgres_default` isn't defined; 875)
[2025-04-05T04:38:38.465+0000] {local_task_job_runner.py:240} INFO - Task exited with return code 1
[2025-04-05T04:38:38.480+0000] {taskinstance.py:3503} INFO - 0 downstream tasks scheduled from follow-on schedule check
[2025-04-05T04:38:38.481+0000] {local_task_job_runner.py:222} INFO - ::endgroup::
