[2025-04-05T04:50:03.990+0000] {local_task_job_runner.py:120} INFO - ::group::Pre task execution logs
[2025-04-05T04:50:04.101+0000] {taskinstance.py:2076} INFO - Dependencies all met for dep_context=non-requeueable deps ti=<TaskInstance: e_commerce_dw_etl.transform.transform_dim_status scheduled__2025-04-03T00:00:00+00:00 [queued]>
[2025-04-05T04:50:04.127+0000] {taskinstance.py:2076} INFO - Dependencies all met for dep_context=requeueable deps ti=<TaskInstance: e_commerce_dw_etl.transform.transform_dim_status scheduled__2025-04-03T00:00:00+00:00 [queued]>
[2025-04-05T04:50:04.130+0000] {taskinstance.py:2306} INFO - Starting attempt 1 of 1
[2025-04-05T04:50:04.169+0000] {taskinstance.py:2330} INFO - Executing <Task(PythonOperator): transform.transform_dim_status> on 2025-04-03 00:00:00+00:00
[2025-04-05T04:50:04.187+0000] {logging_mixin.py:188} WARNING - /home/***/.local/lib/python3.12/site-packages/***/task/task_runner/standard_task_runner.py:61 DeprecationWarning: This process (pid=495) is multi-threaded, use of fork() may lead to deadlocks in the child.
[2025-04-05T04:50:04.189+0000] {standard_task_runner.py:63} INFO - Started process 527 to run task
[2025-04-05T04:50:04.198+0000] {standard_task_runner.py:90} INFO - Running: ['***', 'tasks', 'run', 'e_commerce_dw_etl', 'transform.transform_dim_status', 'scheduled__2025-04-03T00:00:00+00:00', '--job-id', '43', '--raw', '--subdir', 'DAGS_FOLDER/ETL_dag.py', '--cfg-path', '/tmp/tmpc21z44nb']
[2025-04-05T04:50:04.204+0000] {standard_task_runner.py:91} INFO - Job 43: Subtask transform.transform_dim_status
[2025-04-05T04:50:04.297+0000] {task_command.py:426} INFO - Running <TaskInstance: e_commerce_dw_etl.transform.transform_dim_status scheduled__2025-04-03T00:00:00+00:00 [running]> on host 7b82c2aa8826
[2025-04-05T04:50:04.497+0000] {taskinstance.py:2648} INFO - Exporting env vars: AIRFLOW_CTX_DAG_OWNER='***' AIRFLOW_CTX_DAG_ID='e_commerce_dw_etl' AIRFLOW_CTX_TASK_ID='transform.transform_dim_status' AIRFLOW_CTX_EXECUTION_DATE='2025-04-03T00:00:00+00:00' AIRFLOW_CTX_TRY_NUMBER='1' AIRFLOW_CTX_DAG_RUN_ID='scheduled__2025-04-03T00:00:00+00:00'
[2025-04-05T04:50:04.503+0000] {taskinstance.py:430} INFO - ::endgroup::
[2025-04-05T04:50:04.575+0000] {base.py:84} INFO - Using connection ID 'postgres_default' for task execution.
[2025-04-05T04:50:04.604+0000] {base.py:84} INFO - Using connection ID 'postgres_default' for task execution.
[2025-04-05T04:50:04.635+0000] {logging_mixin.py:188} INFO - Lỗi khi insert dữ liệu: duplicate key value violates unique constraint "dim_status_pkey"
DETAIL:  Key (statusid)=(1) already exists.
[2025-04-05T04:50:04.641+0000] {python.py:237} INFO - Done. Returned value was: None
[2025-04-05T04:50:04.644+0000] {taskinstance.py:441} INFO - ::group::Post task execution logs
[2025-04-05T04:50:04.682+0000] {taskinstance.py:1206} INFO - Marking task as SUCCESS. dag_id=e_commerce_dw_etl, task_id=transform.transform_dim_status, run_id=scheduled__2025-04-03T00:00:00+00:00, execution_date=20250403T000000, start_date=20250405T045004, end_date=20250405T045004
[2025-04-05T04:50:04.772+0000] {local_task_job_runner.py:240} INFO - Task exited with return code 0
[2025-04-05T04:50:04.857+0000] {taskinstance.py:3503} INFO - 0 downstream tasks scheduled from follow-on schedule check
[2025-04-05T04:50:04.864+0000] {local_task_job_runner.py:222} INFO - ::endgroup::
[2025-04-05T04:54:08.881+0000] {local_task_job_runner.py:120} INFO - ::group::Pre task execution logs
[2025-04-05T04:54:08.958+0000] {taskinstance.py:2076} INFO - Dependencies all met for dep_context=non-requeueable deps ti=<TaskInstance: e_commerce_dw_etl.transform.transform_dim_status scheduled__2025-04-03T00:00:00+00:00 [queued]>
[2025-04-05T04:54:08.992+0000] {taskinstance.py:2076} INFO - Dependencies all met for dep_context=requeueable deps ti=<TaskInstance: e_commerce_dw_etl.transform.transform_dim_status scheduled__2025-04-03T00:00:00+00:00 [queued]>
[2025-04-05T04:54:08.996+0000] {taskinstance.py:2306} INFO - Starting attempt 1 of 1
[2025-04-05T04:54:09.021+0000] {taskinstance.py:2330} INFO - Executing <Task(PythonOperator): transform.transform_dim_status> on 2025-04-03 00:00:00+00:00
[2025-04-05T04:54:09.046+0000] {logging_mixin.py:188} WARNING - /home/***/.local/lib/python3.12/site-packages/***/task/task_runner/standard_task_runner.py:61 DeprecationWarning: This process (pid=499) is multi-threaded, use of fork() may lead to deadlocks in the child.
[2025-04-05T04:54:09.048+0000] {standard_task_runner.py:90} INFO - Running: ['***', 'tasks', 'run', 'e_commerce_dw_etl', 'transform.transform_dim_status', 'scheduled__2025-04-03T00:00:00+00:00', '--job-id', '50', '--raw', '--subdir', 'DAGS_FOLDER/ETL_dag.py', '--cfg-path', '/tmp/tmpmy_xtspc']
[2025-04-05T04:54:09.053+0000] {standard_task_runner.py:91} INFO - Job 50: Subtask transform.transform_dim_status
[2025-04-05T04:54:09.053+0000] {standard_task_runner.py:63} INFO - Started process 534 to run task
[2025-04-05T04:54:09.145+0000] {task_command.py:426} INFO - Running <TaskInstance: e_commerce_dw_etl.transform.transform_dim_status scheduled__2025-04-03T00:00:00+00:00 [running]> on host 4766eee3ca7d
[2025-04-05T04:54:09.294+0000] {taskinstance.py:2648} INFO - Exporting env vars: AIRFLOW_CTX_DAG_OWNER='***' AIRFLOW_CTX_DAG_ID='e_commerce_dw_etl' AIRFLOW_CTX_TASK_ID='transform.transform_dim_status' AIRFLOW_CTX_EXECUTION_DATE='2025-04-03T00:00:00+00:00' AIRFLOW_CTX_TRY_NUMBER='1' AIRFLOW_CTX_DAG_RUN_ID='scheduled__2025-04-03T00:00:00+00:00'
[2025-04-05T04:54:09.298+0000] {taskinstance.py:430} INFO - ::endgroup::
[2025-04-05T04:54:09.356+0000] {taskinstance.py:441} INFO - ::group::Post task execution logs
[2025-04-05T04:54:09.369+0000] {taskinstance.py:2905} ERROR - Task failed with exception
Traceback (most recent call last):
  File "/home/airflow/.local/lib/python3.12/site-packages/airflow/models/taskinstance.py", line 465, in _execute_task
    result = _execute_callable(context=context, **execute_callable_kwargs)
             ^^^^^^^^^^^^^^^^^^^^^^^^^^^^^^^^^^^^^^^^^^^^^^^^^^^^^^^^^^^^^
  File "/home/airflow/.local/lib/python3.12/site-packages/airflow/models/taskinstance.py", line 432, in _execute_callable
    return execute_callable(context=context, **execute_callable_kwargs)
           ^^^^^^^^^^^^^^^^^^^^^^^^^^^^^^^^^^^^^^^^^^^^^^^^^^^^^^^^^^^^
  File "/home/airflow/.local/lib/python3.12/site-packages/airflow/models/baseoperator.py", line 401, in wrapper
    return func(self, *args, **kwargs)
           ^^^^^^^^^^^^^^^^^^^^^^^^^^^
  File "/home/airflow/.local/lib/python3.12/site-packages/airflow/operators/python.py", line 235, in execute
    return_value = self.execute_callable()
                   ^^^^^^^^^^^^^^^^^^^^^^^
  File "/home/airflow/.local/lib/python3.12/site-packages/airflow/operators/python.py", line 252, in execute_callable
    return self.python_callable(*self.op_args, **self.op_kwargs)
           ^^^^^^^^^^^^^^^^^^^^^^^^^^^^^^^^^^^^^^^^^^^^^^^^^^^^^
  File "/opt/airflow/dags/transform_dim_status.py", line 26, in transform_dim_status
    warehouse_operator.create_table(create_table_qr)
  File "/opt/airflow/dags/postgresql_operator.py", line 10, in create_table
    conn = pg_hook.get_conn()
           ^^^^^^^^^^^^^^^^^^
  File "/home/airflow/.local/lib/python3.12/site-packages/airflow/providers/postgres/hooks/postgres.py", line 145, in get_conn
    conn = deepcopy(self.connection or self.get_connection(conn_id))
                                       ^^^^^^^^^^^^^^^^^^^^^^^^^^^^
  File "/home/airflow/.local/lib/python3.12/site-packages/airflow/hooks/base.py", line 83, in get_connection
    conn = Connection.get_connection_from_secrets(conn_id)
           ^^^^^^^^^^^^^^^^^^^^^^^^^^^^^^^^^^^^^^^^^^^^^^^
  File "/home/airflow/.local/lib/python3.12/site-packages/airflow/models/connection.py", line 519, in get_connection_from_secrets
    raise AirflowNotFoundException(f"The conn_id `{conn_id}` isn't defined")
airflow.exceptions.AirflowNotFoundException: The conn_id `postgres_default` isn't defined
[2025-04-05T04:54:09.382+0000] {taskinstance.py:1206} INFO - Marking task as FAILED. dag_id=e_commerce_dw_etl, task_id=transform.transform_dim_status, run_id=scheduled__2025-04-03T00:00:00+00:00, execution_date=20250403T000000, start_date=20250405T045408, end_date=20250405T045409
[2025-04-05T04:54:09.398+0000] {standard_task_runner.py:110} ERROR - Failed to execute job 50 for task transform.transform_dim_status (The conn_id `postgres_default` isn't defined; 534)
[2025-04-05T04:54:09.438+0000] {local_task_job_runner.py:240} INFO - Task exited with return code 1
[2025-04-05T04:54:09.463+0000] {taskinstance.py:3503} INFO - 0 downstream tasks scheduled from follow-on schedule check
[2025-04-05T04:54:09.464+0000] {local_task_job_runner.py:222} INFO - ::endgroup::
