[2025-04-08T09:21:40.002+0000] {local_task_job_runner.py:120} INFO - ::group::Pre task execution logs
[2025-04-08T09:21:40.038+0000] {taskinstance.py:2076} INFO - Dependencies all met for dep_context=non-requeueable deps ti=<TaskInstance: formula1-etl-pipeline.transform.transform_dim_circuits manual__2025-04-08T09:21:36.165113+00:00 [queued]>
[2025-04-08T09:21:40.050+0000] {taskinstance.py:2076} INFO - Dependencies all met for dep_context=requeueable deps ti=<TaskInstance: formula1-etl-pipeline.transform.transform_dim_circuits manual__2025-04-08T09:21:36.165113+00:00 [queued]>
[2025-04-08T09:21:40.050+0000] {taskinstance.py:2306} INFO - Starting attempt 1 of 1
[2025-04-08T09:21:40.071+0000] {taskinstance.py:2330} INFO - Executing <Task(PythonOperator): transform.transform_dim_circuits> on 2025-04-08 09:21:36.165113+00:00
[2025-04-08T09:21:40.082+0000] {standard_task_runner.py:90} INFO - Running: ['***', 'tasks', 'run', 'formula1-etl-pipeline', 'transform.transform_dim_circuits', 'manual__2025-04-08T09:21:36.165113+00:00', '--job-id', '27', '--raw', '--subdir', 'DAGS_FOLDER/ETL_dag.py', '--cfg-path', '/tmp/tmpkcomzho6']
[2025-04-08T09:21:40.085+0000] {standard_task_runner.py:91} INFO - Job 27: Subtask transform.transform_dim_circuits
[2025-04-08T09:21:40.086+0000] {logging_mixin.py:188} WARNING - /home/***/.local/lib/python3.12/site-packages/***/task/task_runner/standard_task_runner.py:61 DeprecationWarning: This process (pid=241) is multi-threaded, use of fork() may lead to deadlocks in the child.
[2025-04-08T09:21:40.087+0000] {standard_task_runner.py:63} INFO - Started process 254 to run task
[2025-04-08T09:21:40.133+0000] {task_command.py:426} INFO - Running <TaskInstance: formula1-etl-pipeline.transform.transform_dim_circuits manual__2025-04-08T09:21:36.165113+00:00 [running]> on host bbffae879616
[2025-04-08T09:21:40.219+0000] {taskinstance.py:2648} INFO - Exporting env vars: AIRFLOW_CTX_DAG_OWNER='***' AIRFLOW_CTX_DAG_ID='formula1-etl-pipeline' AIRFLOW_CTX_TASK_ID='transform.transform_dim_circuits' AIRFLOW_CTX_EXECUTION_DATE='2025-04-08T09:21:36.165113+00:00' AIRFLOW_CTX_TRY_NUMBER='1' AIRFLOW_CTX_DAG_RUN_ID='manual__2025-04-08T09:21:36.165113+00:00'
[2025-04-08T09:21:40.221+0000] {taskinstance.py:430} INFO - ::endgroup::
[2025-04-08T09:21:40.235+0000] {logging_mixin.py:188} INFO - /opt/***/dataset
[2025-04-08T09:21:40.254+0000] {base.py:84} INFO - Using connection ID 'postgres_default' for task execution.
[2025-04-08T09:21:40.259+0000] {logging_mixin.py:188} INFO - Đã transform và lưu dữ liệu vào bảng.
[2025-04-08T09:21:40.265+0000] {base.py:84} INFO - Using connection ID 'postgres_default' for task execution.
[2025-04-08T09:21:40.278+0000] {logging_mixin.py:188} INFO - Lỗi khi insert dữ liệu: duplicate key value violates unique constraint "dim_circuits_pkey"
DETAIL:  Key (circuitid)=(1) already exists.
[2025-04-08T09:21:40.279+0000] {taskinstance.py:441} INFO - ::group::Post task execution logs
[2025-04-08T09:21:40.279+0000] {taskinstance.py:2905} ERROR - Task failed with exception
Traceback (most recent call last):
  File "/home/airflow/.local/lib/python3.12/site-packages/airflow/models/taskinstance.py", line 465, in _execute_task
    result = _execute_callable(context=context, **execute_callable_kwargs)
             ^^^^^^^^^^^^^^^^^^^^^^^^^^^^^^^^^^^^^^^^^^^^^^^^^^^^^^^^^^^^^
  File "/home/airflow/.local/lib/python3.12/site-packages/airflow/models/taskinstance.py", line 432, in _execute_callable
    return execute_callable(context=context, **execute_callable_kwargs)
           ^^^^^^^^^^^^^^^^^^^^^^^^^^^^^^^^^^^^^^^^^^^^^^^^^^^^^^^^^^^^
  File "/home/airflow/.local/lib/python3.12/site-packages/airflow/models/baseoperator.py", line 401, in wrapper
    return func(self, *args, **kwargs)
           ^^^^^^^^^^^^^^^^^^^^^^^^^^^
  File "/home/airflow/.local/lib/python3.12/site-packages/airflow/operators/python.py", line 235, in execute
    return_value = self.execute_callable()
                   ^^^^^^^^^^^^^^^^^^^^^^^
  File "/home/airflow/.local/lib/python3.12/site-packages/airflow/operators/python.py", line 252, in execute_callable
    return self.python_callable(*self.op_args, **self.op_kwargs)
           ^^^^^^^^^^^^^^^^^^^^^^^^^^^^^^^^^^^^^^^^^^^^^^^^^^^^^
  File "/opt/airflow/dags/transform_dim_circuits.py", line 40, in transform_dim_circuits
    warehouse_operator.insert_table(insert_table_querry, dim_circuits_df)
  File "/opt/airflow/dags/postgresql_operator.py", line 35, in insert_table
    cursor.executemany(query, values)
psycopg2.errors.UniqueViolation: duplicate key value violates unique constraint "dim_circuits_pkey"
DETAIL:  Key (circuitid)=(1) already exists.

[2025-04-08T09:21:40.295+0000] {taskinstance.py:1206} INFO - Marking task as FAILED. dag_id=formula1-etl-pipeline, task_id=transform.transform_dim_circuits, run_id=manual__2025-04-08T09:21:36.165113+00:00, execution_date=20250408T092136, start_date=20250408T092140, end_date=20250408T092140
[2025-04-08T09:21:40.312+0000] {standard_task_runner.py:110} ERROR - Failed to execute job 27 for task transform.transform_dim_circuits (duplicate key value violates unique constraint "dim_circuits_pkey"
DETAIL:  Key (circuitid)=(1) already exists.
; 254)
[2025-04-08T09:21:40.341+0000] {local_task_job_runner.py:240} INFO - Task exited with return code 1
[2025-04-08T09:21:40.352+0000] {local_task_job_runner.py:222} INFO - ::endgroup::
