[2025-04-01T14:29:53.076+0000] {local_task_job_runner.py:120} INFO - ::group::Pre task execution logs
[2025-04-01T14:29:53.143+0000] {taskinstance.py:2076} INFO - Dependencies all met for dep_context=non-requeueable deps ti=<TaskInstance: e_commerce_dw_etl.extract.extract_and_load_to_staging manual__2025-04-01T14:29:51.441789+00:00 [queued]>
[2025-04-01T14:29:53.159+0000] {taskinstance.py:2076} INFO - Dependencies all met for dep_context=requeueable deps ti=<TaskInstance: e_commerce_dw_etl.extract.extract_and_load_to_staging manual__2025-04-01T14:29:51.441789+00:00 [queued]>
[2025-04-01T14:29:53.160+0000] {taskinstance.py:2306} INFO - Starting attempt 1 of 1
[2025-04-01T14:29:53.188+0000] {taskinstance.py:2330} INFO - Executing <Task(PythonOperator): extract.extract_and_load_to_staging> on 2025-04-01 14:29:51.441789+00:00
[2025-04-01T14:29:53.197+0000] {standard_task_runner.py:63} INFO - Started process 244 to run task
[2025-04-01T14:29:53.202+0000] {standard_task_runner.py:90} INFO - Running: ['***', 'tasks', 'run', 'e_commerce_dw_etl', 'extract.extract_and_load_to_staging', 'manual__2025-04-01T14:29:51.441789+00:00', '--job-id', '16', '--raw', '--subdir', 'DAGS_FOLDER/ETL_dag.py', '--cfg-path', '/tmp/tmpqstujs7_']
[2025-04-01T14:29:53.206+0000] {standard_task_runner.py:91} INFO - Job 16: Subtask extract.extract_and_load_to_staging
[2025-04-01T14:29:53.293+0000] {task_command.py:426} INFO - Running <TaskInstance: e_commerce_dw_etl.extract.extract_and_load_to_staging manual__2025-04-01T14:29:51.441789+00:00 [running]> on host 320a2d72aabf
[2025-04-01T14:29:53.430+0000] {taskinstance.py:2648} INFO - Exporting env vars: AIRFLOW_CTX_DAG_OWNER='***' AIRFLOW_CTX_DAG_ID='e_commerce_dw_etl' AIRFLOW_CTX_TASK_ID='extract.extract_and_load_to_staging' AIRFLOW_CTX_EXECUTION_DATE='2025-04-01T14:29:51.441789+00:00' AIRFLOW_CTX_TRY_NUMBER='1' AIRFLOW_CTX_DAG_RUN_ID='manual__2025-04-01T14:29:51.441789+00:00'
[2025-04-01T14:29:53.432+0000] {taskinstance.py:430} INFO - ::endgroup::
[2025-04-01T14:29:53.467+0000] {mysql_operator.py:14} ERROR - Can't connect to mysql database
[2025-04-01T14:29:53.482+0000] {taskinstance.py:441} INFO - ::group::Post task execution logs
[2025-04-01T14:29:53.508+0000] {taskinstance.py:2905} ERROR - Task failed with exception
Traceback (most recent call last):
  File "/home/airflow/.local/lib/python3.10/site-packages/airflow/models/taskinstance.py", line 465, in _execute_task
    result = _execute_callable(context=context, **execute_callable_kwargs)
  File "/home/airflow/.local/lib/python3.10/site-packages/airflow/models/taskinstance.py", line 432, in _execute_callable
    return execute_callable(context=context, **execute_callable_kwargs)
  File "/home/airflow/.local/lib/python3.10/site-packages/airflow/models/baseoperator.py", line 401, in wrapper
    return func(self, *args, **kwargs)
  File "/home/airflow/.local/lib/python3.10/site-packages/airflow/operators/python.py", line 235, in execute
    return_value = self.execute_callable()
  File "/home/airflow/.local/lib/python3.10/site-packages/airflow/operators/python.py", line 252, in execute_callable
    return self.python_callable(*self.op_args, **self.op_kwargs)
  File "/opt/airflow/dags/extract_data.py", line 37, in extract_and_load_to_staging
    df = source_operator.get_data_to_pd(f"SELECT * FROM {table}")
  File "/opt/airflow/plugins/mysql_operator.py", line 17, in get_data_to_pd
    return self.mysqlhook.get_pandas_df(query) #Chạy câu SQL và trả kết quả dưới dạng DataFrame (dùng cho phân tích dữ liệu).
  File "/home/airflow/.local/lib/python3.10/site-packages/airflow/providers/common/sql/hooks/sql.py", line 262, in get_pandas_df
    with closing(self.get_conn()) as conn:
  File "/home/airflow/.local/lib/python3.10/site-packages/airflow/providers/mysql/hooks/mysql.py", line 188, in get_conn
    conn = self.connection or self.get_connection(getattr(self, self.conn_name_attr))
  File "/home/airflow/.local/lib/python3.10/site-packages/airflow/hooks/base.py", line 83, in get_connection
    conn = Connection.get_connection_from_secrets(conn_id)
  File "/home/airflow/.local/lib/python3.10/site-packages/airflow/models/connection.py", line 519, in get_connection_from_secrets
    raise AirflowNotFoundException(f"The conn_id `{conn_id}` isn't defined")
airflow.exceptions.AirflowNotFoundException: The conn_id `mysql` isn't defined
[2025-04-01T14:29:53.537+0000] {taskinstance.py:1206} INFO - Marking task as FAILED. dag_id=e_commerce_dw_etl, task_id=extract.extract_and_load_to_staging, run_id=manual__2025-04-01T14:29:51.441789+00:00, execution_date=20250401T142951, start_date=20250401T142953, end_date=20250401T142953
[2025-04-01T14:29:53.575+0000] {standard_task_runner.py:110} ERROR - Failed to execute job 16 for task extract.extract_and_load_to_staging (The conn_id `mysql` isn't defined; 244)
[2025-04-01T14:29:53.616+0000] {local_task_job_runner.py:240} INFO - Task exited with return code 1
[2025-04-01T14:29:53.680+0000] {taskinstance.py:3503} INFO - 0 downstream tasks scheduled from follow-on schedule check
[2025-04-01T14:29:53.692+0000] {local_task_job_runner.py:222} INFO - ::endgroup::
