[2025-04-08T09:27:39.915+0000] {local_task_job_runner.py:120} INFO - ::group::Pre task execution logs
[2025-04-08T09:27:39.999+0000] {taskinstance.py:2076} INFO - Dependencies all met for dep_context=non-requeueable deps ti=<TaskInstance: formula1-etl-pipeline.transform.transform_dim_races scheduled__2025-04-05T00:00:00+00:00 [queued]>
[2025-04-08T09:27:40.020+0000] {taskinstance.py:2076} INFO - Dependencies all met for dep_context=requeueable deps ti=<TaskInstance: formula1-etl-pipeline.transform.transform_dim_races scheduled__2025-04-05T00:00:00+00:00 [queued]>
[2025-04-08T09:27:40.024+0000] {taskinstance.py:2306} INFO - Starting attempt 1 of 1
[2025-04-08T09:27:40.076+0000] {taskinstance.py:2330} INFO - Executing <Task(PythonOperator): transform.transform_dim_races> on 2025-04-05 00:00:00+00:00
[2025-04-08T09:27:40.102+0000] {logging_mixin.py:188} WARNING - /home/***/.local/lib/python3.12/site-packages/***/task/task_runner/standard_task_runner.py:61 DeprecationWarning: This process (pid=744) is multi-threaded, use of fork() may lead to deadlocks in the child.
[2025-04-08T09:27:40.112+0000] {standard_task_runner.py:63} INFO - Started process 769 to run task
[2025-04-08T09:27:40.111+0000] {standard_task_runner.py:90} INFO - Running: ['***', 'tasks', 'run', 'formula1-etl-pipeline', 'transform.transform_dim_races', 'scheduled__2025-04-05T00:00:00+00:00', '--job-id', '60', '--raw', '--subdir', 'DAGS_FOLDER/ETL_dag.py', '--cfg-path', '/tmp/tmpeu8omtz5']
[2025-04-08T09:27:40.120+0000] {standard_task_runner.py:91} INFO - Job 60: Subtask transform.transform_dim_races
[2025-04-08T09:27:40.289+0000] {task_command.py:426} INFO - Running <TaskInstance: formula1-etl-pipeline.transform.transform_dim_races scheduled__2025-04-05T00:00:00+00:00 [running]> on host 1c2d39091a25
[2025-04-08T09:27:40.482+0000] {taskinstance.py:2648} INFO - Exporting env vars: AIRFLOW_CTX_DAG_OWNER='***' AIRFLOW_CTX_DAG_ID='formula1-etl-pipeline' AIRFLOW_CTX_TASK_ID='transform.transform_dim_races' AIRFLOW_CTX_EXECUTION_DATE='2025-04-05T00:00:00+00:00' AIRFLOW_CTX_TRY_NUMBER='1' AIRFLOW_CTX_DAG_RUN_ID='scheduled__2025-04-05T00:00:00+00:00'
[2025-04-08T09:27:40.486+0000] {taskinstance.py:430} INFO - ::endgroup::
[2025-04-08T09:27:40.580+0000] {base.py:84} INFO - Using connection ID 'postgres_default' for task execution.
[2025-04-08T09:27:40.594+0000] {logging_mixin.py:188} INFO - Đã tạo bảng thành công.
[2025-04-08T09:27:40.603+0000] {base.py:84} INFO - Using connection ID 'postgres_default' for task execution.
[2025-04-08T09:27:40.713+0000] {logging_mixin.py:188} INFO - Lỗi khi insert dữ liệu: duplicate key value violates unique constraint "dim_races_pkey"
DETAIL:  Key (raceid)=(1) already exists.
[2025-04-08T09:27:40.714+0000] {taskinstance.py:441} INFO - ::group::Post task execution logs
[2025-04-08T09:27:40.715+0000] {taskinstance.py:2905} ERROR - Task failed with exception
Traceback (most recent call last):
  File "/home/airflow/.local/lib/python3.12/site-packages/airflow/models/taskinstance.py", line 465, in _execute_task
    result = _execute_callable(context=context, **execute_callable_kwargs)
             ^^^^^^^^^^^^^^^^^^^^^^^^^^^^^^^^^^^^^^^^^^^^^^^^^^^^^^^^^^^^^
  File "/home/airflow/.local/lib/python3.12/site-packages/airflow/models/taskinstance.py", line 432, in _execute_callable
    return execute_callable(context=context, **execute_callable_kwargs)
           ^^^^^^^^^^^^^^^^^^^^^^^^^^^^^^^^^^^^^^^^^^^^^^^^^^^^^^^^^^^^
  File "/home/airflow/.local/lib/python3.12/site-packages/airflow/models/baseoperator.py", line 401, in wrapper
    return func(self, *args, **kwargs)
           ^^^^^^^^^^^^^^^^^^^^^^^^^^^
  File "/home/airflow/.local/lib/python3.12/site-packages/airflow/operators/python.py", line 235, in execute
    return_value = self.execute_callable()
                   ^^^^^^^^^^^^^^^^^^^^^^^
  File "/home/airflow/.local/lib/python3.12/site-packages/airflow/operators/python.py", line 252, in execute_callable
    return self.python_callable(*self.op_args, **self.op_kwargs)
           ^^^^^^^^^^^^^^^^^^^^^^^^^^^^^^^^^^^^^^^^^^^^^^^^^^^^^
  File "/opt/airflow/dags/transform_dim_races.py", line 45, in transform_dim_races
    warehouse_operator.insert_table(insert_table_querry, dim_races_df)
  File "/opt/airflow/dags/postgresql_operator.py", line 35, in insert_table
    cursor.executemany(query, values)
psycopg2.errors.UniqueViolation: duplicate key value violates unique constraint "dim_races_pkey"
DETAIL:  Key (raceid)=(1) already exists.

[2025-04-08T09:27:40.738+0000] {taskinstance.py:1206} INFO - Marking task as FAILED. dag_id=formula1-etl-pipeline, task_id=transform.transform_dim_races, run_id=scheduled__2025-04-05T00:00:00+00:00, execution_date=20250405T000000, start_date=20250408T092740, end_date=20250408T092740
[2025-04-08T09:27:40.763+0000] {standard_task_runner.py:110} ERROR - Failed to execute job 60 for task transform.transform_dim_races (duplicate key value violates unique constraint "dim_races_pkey"
DETAIL:  Key (raceid)=(1) already exists.
; 769)
[2025-04-08T09:27:40.792+0000] {local_task_job_runner.py:240} INFO - Task exited with return code 1
[2025-04-08T09:27:40.809+0000] {local_task_job_runner.py:222} INFO - ::endgroup::
