[2025-04-05T04:49:56.908+0000] {local_task_job_runner.py:120} INFO - ::group::Pre task execution logs
[2025-04-05T04:49:57.018+0000] {taskinstance.py:2076} INFO - Dependencies all met for dep_context=non-requeueable deps ti=<TaskInstance: e_commerce_dw_etl.transform.transform_dim_drivers scheduled__2025-03-30T00:00:00+00:00 [queued]>
[2025-04-05T04:49:57.040+0000] {taskinstance.py:2076} INFO - Dependencies all met for dep_context=requeueable deps ti=<TaskInstance: e_commerce_dw_etl.transform.transform_dim_drivers scheduled__2025-03-30T00:00:00+00:00 [queued]>
[2025-04-05T04:49:57.044+0000] {taskinstance.py:2306} INFO - Starting attempt 1 of 1
[2025-04-05T04:49:57.076+0000] {taskinstance.py:2330} INFO - Executing <Task(PythonOperator): transform.transform_dim_drivers> on 2025-03-30 00:00:00+00:00
[2025-04-05T04:49:57.106+0000] {logging_mixin.py:188} WARNING - /home/***/.local/lib/python3.12/site-packages/***/task/task_runner/standard_task_runner.py:61 DeprecationWarning: This process (pid=410) is multi-threaded, use of fork() may lead to deadlocks in the child.
[2025-04-05T04:49:57.113+0000] {standard_task_runner.py:63} INFO - Started process 440 to run task
[2025-04-05T04:49:57.108+0000] {standard_task_runner.py:90} INFO - Running: ['***', 'tasks', 'run', 'e_commerce_dw_etl', 'transform.transform_dim_drivers', 'scheduled__2025-03-30T00:00:00+00:00', '--job-id', '17', '--raw', '--subdir', 'DAGS_FOLDER/ETL_dag.py', '--cfg-path', '/tmp/tmpuhhknxeb']
[2025-04-05T04:49:57.117+0000] {standard_task_runner.py:91} INFO - Job 17: Subtask transform.transform_dim_drivers
[2025-04-05T04:49:57.256+0000] {task_command.py:426} INFO - Running <TaskInstance: e_commerce_dw_etl.transform.transform_dim_drivers scheduled__2025-03-30T00:00:00+00:00 [running]> on host 7b82c2aa8826
[2025-04-05T04:49:57.469+0000] {taskinstance.py:2648} INFO - Exporting env vars: AIRFLOW_CTX_DAG_OWNER='***' AIRFLOW_CTX_DAG_ID='e_commerce_dw_etl' AIRFLOW_CTX_TASK_ID='transform.transform_dim_drivers' AIRFLOW_CTX_EXECUTION_DATE='2025-03-30T00:00:00+00:00' AIRFLOW_CTX_TRY_NUMBER='1' AIRFLOW_CTX_DAG_RUN_ID='scheduled__2025-03-30T00:00:00+00:00'
[2025-04-05T04:49:57.476+0000] {taskinstance.py:430} INFO - ::endgroup::
[2025-04-05T04:49:57.633+0000] {base.py:84} INFO - Using connection ID 'postgres_default' for task execution.
[2025-04-05T04:49:57.711+0000] {base.py:84} INFO - Using connection ID 'postgres_default' for task execution.
[2025-04-05T04:49:57.956+0000] {logging_mixin.py:188} INFO - Lỗi khi insert dữ liệu: duplicate key value violates unique constraint "dim_drivers_pkey"
DETAIL:  Key (driverid)=(1) already exists.
[2025-04-05T04:49:57.958+0000] {python.py:237} INFO - Done. Returned value was: None
[2025-04-05T04:49:57.963+0000] {taskinstance.py:441} INFO - ::group::Post task execution logs
[2025-04-05T04:49:57.999+0000] {taskinstance.py:1206} INFO - Marking task as SUCCESS. dag_id=e_commerce_dw_etl, task_id=transform.transform_dim_drivers, run_id=scheduled__2025-03-30T00:00:00+00:00, execution_date=20250330T000000, start_date=20250405T044957, end_date=20250405T044957
[2025-04-05T04:49:58.120+0000] {local_task_job_runner.py:240} INFO - Task exited with return code 0
[2025-04-05T04:49:58.192+0000] {taskinstance.py:3503} INFO - 1 downstream tasks scheduled from follow-on schedule check
[2025-04-05T04:49:58.199+0000] {local_task_job_runner.py:222} INFO - ::endgroup::
[2025-04-05T04:54:02.357+0000] {local_task_job_runner.py:120} INFO - ::group::Pre task execution logs
[2025-04-05T04:54:02.475+0000] {taskinstance.py:2076} INFO - Dependencies all met for dep_context=non-requeueable deps ti=<TaskInstance: e_commerce_dw_etl.transform.transform_dim_drivers scheduled__2025-03-30T00:00:00+00:00 [queued]>
[2025-04-05T04:54:02.494+0000] {taskinstance.py:2076} INFO - Dependencies all met for dep_context=requeueable deps ti=<TaskInstance: e_commerce_dw_etl.transform.transform_dim_drivers scheduled__2025-03-30T00:00:00+00:00 [queued]>
[2025-04-05T04:54:02.500+0000] {taskinstance.py:2306} INFO - Starting attempt 1 of 1
[2025-04-05T04:54:02.536+0000] {taskinstance.py:2330} INFO - Executing <Task(PythonOperator): transform.transform_dim_drivers> on 2025-03-30 00:00:00+00:00
[2025-04-05T04:54:02.565+0000] {logging_mixin.py:188} WARNING - /home/***/.local/lib/python3.12/site-packages/***/task/task_runner/standard_task_runner.py:61 DeprecationWarning: This process (pid=359) is multi-threaded, use of fork() may lead to deadlocks in the child.
[2025-04-05T04:54:02.568+0000] {standard_task_runner.py:63} INFO - Started process 409 to run task
[2025-04-05T04:54:02.575+0000] {standard_task_runner.py:90} INFO - Running: ['***', 'tasks', 'run', 'e_commerce_dw_etl', 'transform.transform_dim_drivers', 'scheduled__2025-03-30T00:00:00+00:00', '--job-id', '22', '--raw', '--subdir', 'DAGS_FOLDER/ETL_dag.py', '--cfg-path', '/tmp/tmp8dpgly8m']
[2025-04-05T04:54:02.582+0000] {standard_task_runner.py:91} INFO - Job 22: Subtask transform.transform_dim_drivers
[2025-04-05T04:54:02.767+0000] {task_command.py:426} INFO - Running <TaskInstance: e_commerce_dw_etl.transform.transform_dim_drivers scheduled__2025-03-30T00:00:00+00:00 [running]> on host 4766eee3ca7d
[2025-04-05T04:54:03.042+0000] {taskinstance.py:2648} INFO - Exporting env vars: AIRFLOW_CTX_DAG_OWNER='***' AIRFLOW_CTX_DAG_ID='e_commerce_dw_etl' AIRFLOW_CTX_TASK_ID='transform.transform_dim_drivers' AIRFLOW_CTX_EXECUTION_DATE='2025-03-30T00:00:00+00:00' AIRFLOW_CTX_TRY_NUMBER='1' AIRFLOW_CTX_DAG_RUN_ID='scheduled__2025-03-30T00:00:00+00:00'
[2025-04-05T04:54:03.053+0000] {taskinstance.py:430} INFO - ::endgroup::
[2025-04-05T04:54:03.261+0000] {taskinstance.py:441} INFO - ::group::Post task execution logs
[2025-04-05T04:54:03.305+0000] {taskinstance.py:2905} ERROR - Task failed with exception
Traceback (most recent call last):
  File "/home/airflow/.local/lib/python3.12/site-packages/airflow/models/taskinstance.py", line 465, in _execute_task
    result = _execute_callable(context=context, **execute_callable_kwargs)
             ^^^^^^^^^^^^^^^^^^^^^^^^^^^^^^^^^^^^^^^^^^^^^^^^^^^^^^^^^^^^^
  File "/home/airflow/.local/lib/python3.12/site-packages/airflow/models/taskinstance.py", line 432, in _execute_callable
    return execute_callable(context=context, **execute_callable_kwargs)
           ^^^^^^^^^^^^^^^^^^^^^^^^^^^^^^^^^^^^^^^^^^^^^^^^^^^^^^^^^^^^
  File "/home/airflow/.local/lib/python3.12/site-packages/airflow/models/baseoperator.py", line 401, in wrapper
    return func(self, *args, **kwargs)
           ^^^^^^^^^^^^^^^^^^^^^^^^^^^
  File "/home/airflow/.local/lib/python3.12/site-packages/airflow/operators/python.py", line 235, in execute
    return_value = self.execute_callable()
                   ^^^^^^^^^^^^^^^^^^^^^^^
  File "/home/airflow/.local/lib/python3.12/site-packages/airflow/operators/python.py", line 252, in execute_callable
    return self.python_callable(*self.op_args, **self.op_kwargs)
           ^^^^^^^^^^^^^^^^^^^^^^^^^^^^^^^^^^^^^^^^^^^^^^^^^^^^^
  File "/opt/airflow/dags/transform_dim_drivers.py", line 39, in transform_dim_drivers
    warehouse_operator.create_table(create_table_qr)
  File "/opt/airflow/dags/postgresql_operator.py", line 10, in create_table
    conn = pg_hook.get_conn()
           ^^^^^^^^^^^^^^^^^^
  File "/home/airflow/.local/lib/python3.12/site-packages/airflow/providers/postgres/hooks/postgres.py", line 145, in get_conn
    conn = deepcopy(self.connection or self.get_connection(conn_id))
                                       ^^^^^^^^^^^^^^^^^^^^^^^^^^^^
  File "/home/airflow/.local/lib/python3.12/site-packages/airflow/hooks/base.py", line 83, in get_connection
    conn = Connection.get_connection_from_secrets(conn_id)
           ^^^^^^^^^^^^^^^^^^^^^^^^^^^^^^^^^^^^^^^^^^^^^^^
  File "/home/airflow/.local/lib/python3.12/site-packages/airflow/models/connection.py", line 519, in get_connection_from_secrets
    raise AirflowNotFoundException(f"The conn_id `{conn_id}` isn't defined")
airflow.exceptions.AirflowNotFoundException: The conn_id `postgres_default` isn't defined
[2025-04-05T04:54:03.373+0000] {taskinstance.py:1206} INFO - Marking task as FAILED. dag_id=e_commerce_dw_etl, task_id=transform.transform_dim_drivers, run_id=scheduled__2025-03-30T00:00:00+00:00, execution_date=20250330T000000, start_date=20250405T045402, end_date=20250405T045403
[2025-04-05T04:54:03.409+0000] {standard_task_runner.py:110} ERROR - Failed to execute job 22 for task transform.transform_dim_drivers (The conn_id `postgres_default` isn't defined; 409)
[2025-04-05T04:54:03.489+0000] {local_task_job_runner.py:240} INFO - Task exited with return code 1
[2025-04-05T04:54:03.567+0000] {taskinstance.py:3503} INFO - 0 downstream tasks scheduled from follow-on schedule check
[2025-04-05T04:54:03.576+0000] {local_task_job_runner.py:222} INFO - ::endgroup::
