[2025-04-08T09:27:42.929+0000] {local_task_job_runner.py:120} INFO - ::group::Pre task execution logs
[2025-04-08T09:27:43.053+0000] {taskinstance.py:2076} INFO - Dependencies all met for dep_context=non-requeueable deps ti=<TaskInstance: formula1-etl-pipeline.transform.transform_dim_status manual__2025-04-08T09:27:26.361740+00:00 [queued]>
[2025-04-08T09:27:43.073+0000] {taskinstance.py:2076} INFO - Dependencies all met for dep_context=requeueable deps ti=<TaskInstance: formula1-etl-pipeline.transform.transform_dim_status manual__2025-04-08T09:27:26.361740+00:00 [queued]>
[2025-04-08T09:27:43.093+0000] {taskinstance.py:2306} INFO - Starting attempt 1 of 1
[2025-04-08T09:27:43.135+0000] {taskinstance.py:2330} INFO - Executing <Task(PythonOperator): transform.transform_dim_status> on 2025-04-08 09:27:26.361740+00:00
[2025-04-08T09:27:43.205+0000] {logging_mixin.py:188} WARNING - /home/***/.local/lib/python3.12/site-packages/***/task/task_runner/standard_task_runner.py:61 DeprecationWarning: This process (pid=784) is multi-threaded, use of fork() may lead to deadlocks in the child.
[2025-04-08T09:27:43.209+0000] {standard_task_runner.py:63} INFO - Started process 807 to run task
[2025-04-08T09:27:43.213+0000] {standard_task_runner.py:90} INFO - Running: ['***', 'tasks', 'run', 'formula1-etl-pipeline', 'transform.transform_dim_status', 'manual__2025-04-08T09:27:26.361740+00:00', '--job-id', '64', '--raw', '--subdir', 'DAGS_FOLDER/ETL_dag.py', '--cfg-path', '/tmp/tmpw_s0odmi']
[2025-04-08T09:27:43.228+0000] {standard_task_runner.py:91} INFO - Job 64: Subtask transform.transform_dim_status
[2025-04-08T09:27:43.388+0000] {task_command.py:426} INFO - Running <TaskInstance: formula1-etl-pipeline.transform.transform_dim_status manual__2025-04-08T09:27:26.361740+00:00 [running]> on host 1c2d39091a25
[2025-04-08T09:27:43.797+0000] {taskinstance.py:2648} INFO - Exporting env vars: AIRFLOW_CTX_DAG_OWNER='***' AIRFLOW_CTX_DAG_ID='formula1-etl-pipeline' AIRFLOW_CTX_TASK_ID='transform.transform_dim_status' AIRFLOW_CTX_EXECUTION_DATE='2025-04-08T09:27:26.361740+00:00' AIRFLOW_CTX_TRY_NUMBER='1' AIRFLOW_CTX_DAG_RUN_ID='manual__2025-04-08T09:27:26.361740+00:00'
[2025-04-08T09:27:43.800+0000] {taskinstance.py:430} INFO - ::endgroup::
[2025-04-08T09:27:43.910+0000] {base.py:84} INFO - Using connection ID 'postgres_default' for task execution.
[2025-04-08T09:27:43.933+0000] {logging_mixin.py:188} INFO - Đã tạo bảng thành công.
[2025-04-08T09:27:43.957+0000] {base.py:84} INFO - Using connection ID 'postgres_default' for task execution.
[2025-04-08T09:27:44.032+0000] {logging_mixin.py:188} INFO - Lỗi khi insert dữ liệu: duplicate key value violates unique constraint "dim_status_pkey"
DETAIL:  Key (statusid)=(1) already exists.
[2025-04-08T09:27:44.033+0000] {taskinstance.py:441} INFO - ::group::Post task execution logs
[2025-04-08T09:27:44.058+0000] {taskinstance.py:2905} ERROR - Task failed with exception
Traceback (most recent call last):
  File "/home/airflow/.local/lib/python3.12/site-packages/airflow/models/taskinstance.py", line 465, in _execute_task
    result = _execute_callable(context=context, **execute_callable_kwargs)
             ^^^^^^^^^^^^^^^^^^^^^^^^^^^^^^^^^^^^^^^^^^^^^^^^^^^^^^^^^^^^^
  File "/home/airflow/.local/lib/python3.12/site-packages/airflow/models/taskinstance.py", line 432, in _execute_callable
    return execute_callable(context=context, **execute_callable_kwargs)
           ^^^^^^^^^^^^^^^^^^^^^^^^^^^^^^^^^^^^^^^^^^^^^^^^^^^^^^^^^^^^
  File "/home/airflow/.local/lib/python3.12/site-packages/airflow/models/baseoperator.py", line 401, in wrapper
    return func(self, *args, **kwargs)
           ^^^^^^^^^^^^^^^^^^^^^^^^^^^
  File "/home/airflow/.local/lib/python3.12/site-packages/airflow/operators/python.py", line 235, in execute
    return_value = self.execute_callable()
                   ^^^^^^^^^^^^^^^^^^^^^^^
  File "/home/airflow/.local/lib/python3.12/site-packages/airflow/operators/python.py", line 252, in execute_callable
    return self.python_callable(*self.op_args, **self.op_kwargs)
           ^^^^^^^^^^^^^^^^^^^^^^^^^^^^^^^^^^^^^^^^^^^^^^^^^^^^^
  File "/opt/airflow/dags/transform_dim_status.py", line 33, in transform_dim_status
    warehouse_operator.insert_table(insert_table_querry, dim_status_df)
  File "/opt/airflow/dags/postgresql_operator.py", line 35, in insert_table
    cursor.executemany(query, values)
psycopg2.errors.UniqueViolation: duplicate key value violates unique constraint "dim_status_pkey"
DETAIL:  Key (statusid)=(1) already exists.

[2025-04-08T09:27:44.193+0000] {taskinstance.py:1206} INFO - Marking task as FAILED. dag_id=formula1-etl-pipeline, task_id=transform.transform_dim_status, run_id=manual__2025-04-08T09:27:26.361740+00:00, execution_date=20250408T092726, start_date=20250408T092743, end_date=20250408T092744
[2025-04-08T09:27:44.229+0000] {standard_task_runner.py:110} ERROR - Failed to execute job 64 for task transform.transform_dim_status (duplicate key value violates unique constraint "dim_status_pkey"
DETAIL:  Key (statusid)=(1) already exists.
; 807)
[2025-04-08T09:27:44.298+0000] {local_task_job_runner.py:240} INFO - Task exited with return code 1
[2025-04-08T09:27:44.353+0000] {taskinstance.py:3503} INFO - 0 downstream tasks scheduled from follow-on schedule check
[2025-04-08T09:27:44.367+0000] {local_task_job_runner.py:222} INFO - ::endgroup::
