[2025-04-03T14:33:31.781+0000] {local_task_job_runner.py:120} INFO - ::group::Pre task execution logs
[2025-04-03T14:33:31.831+0000] {taskinstance.py:2076} INFO - Dependencies all met for dep_context=non-requeueable deps ti=<TaskInstance: e_commerce_dw_etl.transform.transform_dim_circuits manual__2025-04-03T14:33:29.186765+00:00 [queued]>
[2025-04-03T14:33:31.847+0000] {taskinstance.py:2076} INFO - Dependencies all met for dep_context=requeueable deps ti=<TaskInstance: e_commerce_dw_etl.transform.transform_dim_circuits manual__2025-04-03T14:33:29.186765+00:00 [queued]>
[2025-04-03T14:33:31.848+0000] {taskinstance.py:2306} INFO - Starting attempt 1 of 1
[2025-04-03T14:33:31.877+0000] {taskinstance.py:2330} INFO - Executing <Task(PythonOperator): transform.transform_dim_circuits> on 2025-04-03 14:33:29.186765+00:00
[2025-04-03T14:33:31.900+0000] {logging_mixin.py:188} WARNING - /home/***/.local/lib/python3.12/site-packages/***/task/task_runner/standard_task_runner.py:61 DeprecationWarning: This process (pid=244) is multi-threaded, use of fork() may lead to deadlocks in the child.
[2025-04-03T14:33:31.903+0000] {standard_task_runner.py:63} INFO - Started process 290 to run task
[2025-04-03T14:33:31.909+0000] {standard_task_runner.py:90} INFO - Running: ['***', 'tasks', 'run', 'e_commerce_dw_etl', 'transform.transform_dim_circuits', 'manual__2025-04-03T14:33:29.186765+00:00', '--job-id', '2', '--raw', '--subdir', 'DAGS_FOLDER/ETL_dag.py', '--cfg-path', '/tmp/tmp67w30zh8']
[2025-04-03T14:33:31.913+0000] {standard_task_runner.py:91} INFO - Job 2: Subtask transform.transform_dim_circuits
[2025-04-03T14:33:32.026+0000] {task_command.py:426} INFO - Running <TaskInstance: e_commerce_dw_etl.transform.transform_dim_circuits manual__2025-04-03T14:33:29.186765+00:00 [running]> on host 4817eee54a38
[2025-04-03T14:33:32.200+0000] {taskinstance.py:2648} INFO - Exporting env vars: AIRFLOW_CTX_DAG_OWNER='***' AIRFLOW_CTX_DAG_ID='e_commerce_dw_etl' AIRFLOW_CTX_TASK_ID='transform.transform_dim_circuits' AIRFLOW_CTX_EXECUTION_DATE='2025-04-03T14:33:29.186765+00:00' AIRFLOW_CTX_TRY_NUMBER='1' AIRFLOW_CTX_DAG_RUN_ID='manual__2025-04-03T14:33:29.186765+00:00'
[2025-04-03T14:33:32.204+0000] {taskinstance.py:430} INFO - ::endgroup::
[2025-04-03T14:33:32.242+0000] {logging_mixin.py:188} INFO - /opt/***/dataset
[2025-04-03T14:33:32.270+0000] {logging_mixin.py:188} INFO - đã đọc được circuits
[2025-04-03T14:33:32.275+0000] {logging_mixin.py:188} INFO - tạo dc postgres
[2025-04-03T14:33:32.296+0000] {taskinstance.py:441} INFO - ::group::Post task execution logs
[2025-04-03T14:33:32.326+0000] {taskinstance.py:2905} ERROR - Task failed with exception
Traceback (most recent call last):
  File "/home/airflow/.local/lib/python3.12/site-packages/airflow/models/taskinstance.py", line 465, in _execute_task
    result = _execute_callable(context=context, **execute_callable_kwargs)
             ^^^^^^^^^^^^^^^^^^^^^^^^^^^^^^^^^^^^^^^^^^^^^^^^^^^^^^^^^^^^^
  File "/home/airflow/.local/lib/python3.12/site-packages/airflow/models/taskinstance.py", line 432, in _execute_callable
    return execute_callable(context=context, **execute_callable_kwargs)
           ^^^^^^^^^^^^^^^^^^^^^^^^^^^^^^^^^^^^^^^^^^^^^^^^^^^^^^^^^^^^
  File "/home/airflow/.local/lib/python3.12/site-packages/airflow/models/baseoperator.py", line 401, in wrapper
    return func(self, *args, **kwargs)
           ^^^^^^^^^^^^^^^^^^^^^^^^^^^
  File "/home/airflow/.local/lib/python3.12/site-packages/airflow/operators/python.py", line 235, in execute
    return_value = self.execute_callable()
                   ^^^^^^^^^^^^^^^^^^^^^^^
  File "/home/airflow/.local/lib/python3.12/site-packages/airflow/operators/python.py", line 252, in execute_callable
    return self.python_callable(*self.op_args, **self.op_kwargs)
           ^^^^^^^^^^^^^^^^^^^^^^^^^^^^^^^^^^^^^^^^^^^^^^^^^^^^^
  File "/opt/airflow/dags/transform_dim_circuits.py", line 35, in transform_dim_circuits
    warehouse_operator.create_table(create_table_qr)
  File "/opt/airflow/dags/postgresql_operator.py", line 12, in create_table
    conn = pg_hook.get_conn()
           ^^^^^^^^^^^^^^^^^^
  File "/home/airflow/.local/lib/python3.12/site-packages/airflow/providers/postgres/hooks/postgres.py", line 145, in get_conn
    conn = deepcopy(self.connection or self.get_connection(conn_id))
                                       ^^^^^^^^^^^^^^^^^^^^^^^^^^^^
  File "/home/airflow/.local/lib/python3.12/site-packages/airflow/hooks/base.py", line 83, in get_connection
    conn = Connection.get_connection_from_secrets(conn_id)
           ^^^^^^^^^^^^^^^^^^^^^^^^^^^^^^^^^^^^^^^^^^^^^^^
  File "/home/airflow/.local/lib/python3.12/site-packages/airflow/models/connection.py", line 519, in get_connection_from_secrets
    raise AirflowNotFoundException(f"The conn_id `{conn_id}` isn't defined")
airflow.exceptions.AirflowNotFoundException: The conn_id `postgres_default` isn't defined
[2025-04-03T14:33:32.351+0000] {taskinstance.py:1206} INFO - Marking task as FAILED. dag_id=e_commerce_dw_etl, task_id=transform.transform_dim_circuits, run_id=manual__2025-04-03T14:33:29.186765+00:00, execution_date=20250403T143329, start_date=20250403T143331, end_date=20250403T143332
[2025-04-03T14:33:32.387+0000] {standard_task_runner.py:110} ERROR - Failed to execute job 2 for task transform.transform_dim_circuits (The conn_id `postgres_default` isn't defined; 290)
[2025-04-03T14:33:32.451+0000] {local_task_job_runner.py:240} INFO - Task exited with return code 1
[2025-04-03T14:33:32.479+0000] {taskinstance.py:3503} INFO - 0 downstream tasks scheduled from follow-on schedule check
[2025-04-03T14:33:32.490+0000] {local_task_job_runner.py:222} INFO - ::endgroup::
