[2025-04-08T09:39:04.231+0000] {local_task_job_runner.py:120} INFO - ::group::Pre task execution logs
[2025-04-08T09:39:04.258+0000] {taskinstance.py:2076} INFO - Dependencies all met for dep_context=non-requeueable deps ti=<TaskInstance: formula1-etl-pipeline.load.transform_fact_race_results manual__2025-04-08T09:38:59.375674+00:00 [queued]>
[2025-04-08T09:39:04.266+0000] {taskinstance.py:2076} INFO - Dependencies all met for dep_context=requeueable deps ti=<TaskInstance: formula1-etl-pipeline.load.transform_fact_race_results manual__2025-04-08T09:38:59.375674+00:00 [queued]>
[2025-04-08T09:39:04.266+0000] {taskinstance.py:2306} INFO - Starting attempt 1 of 1
[2025-04-08T09:39:04.279+0000] {taskinstance.py:2330} INFO - Executing <Task(PythonOperator): load.transform_fact_race_results> on 2025-04-08 09:38:59.375674+00:00
[2025-04-08T09:39:04.287+0000] {standard_task_runner.py:90} INFO - Running: ['***', 'tasks', 'run', 'formula1-etl-pipeline', 'load.transform_fact_race_results', 'manual__2025-04-08T09:38:59.375674+00:00', '--job-id', '88', '--raw', '--subdir', 'DAGS_FOLDER/ETL_dag.py', '--cfg-path', '/tmp/tmpjcu4z6ns']
[2025-04-08T09:39:04.289+0000] {standard_task_runner.py:91} INFO - Job 88: Subtask load.transform_fact_race_results
[2025-04-08T09:39:04.289+0000] {logging_mixin.py:188} WARNING - /home/***/.local/lib/python3.12/site-packages/***/task/task_runner/standard_task_runner.py:61 DeprecationWarning: This process (pid=316) is multi-threaded, use of fork() may lead to deadlocks in the child.
[2025-04-08T09:39:04.290+0000] {standard_task_runner.py:63} INFO - Started process 318 to run task
[2025-04-08T09:39:04.326+0000] {task_command.py:426} INFO - Running <TaskInstance: formula1-etl-pipeline.load.transform_fact_race_results manual__2025-04-08T09:38:59.375674+00:00 [running]> on host 1c2d39091a25
[2025-04-08T09:39:04.391+0000] {taskinstance.py:2648} INFO - Exporting env vars: AIRFLOW_CTX_DAG_OWNER='***' AIRFLOW_CTX_DAG_ID='formula1-etl-pipeline' AIRFLOW_CTX_TASK_ID='load.transform_fact_race_results' AIRFLOW_CTX_EXECUTION_DATE='2025-04-08T09:38:59.375674+00:00' AIRFLOW_CTX_TRY_NUMBER='1' AIRFLOW_CTX_DAG_RUN_ID='manual__2025-04-08T09:38:59.375674+00:00'
[2025-04-08T09:39:04.392+0000] {taskinstance.py:430} INFO - ::endgroup::
[2025-04-08T09:39:04.483+0000] {logging_mixin.py:188} INFO - Các cột trong DataFrame sau khi merge:
[2025-04-08T09:39:04.484+0000] {logging_mixin.py:188} INFO - Index(['resultId', 'raceId', 'driverId', 'constructorId', 'number', 'grid',
       'position', 'positionText', 'positionOrder', 'points', 'laps', 'time_x',
       'milliseconds', 'fastestLap', 'rank', 'fastestLapTime',
       'fastestLapSpeed', 'statusId', 'year', 'round', 'circuitId', 'name',
       'date', 'time_y', 'url', 'fp1_date', 'fp1_time', 'fp2_date', 'fp2_time',
       'fp3_date', 'fp3_time', 'quali_date', 'quali_time', 'sprint_date',
       'sprint_time'],
      dtype='object')
[2025-04-08T09:39:04.567+0000] {base.py:84} INFO - Using connection ID 'postgres_default' for task execution.
[2025-04-08T09:39:04.572+0000] {logging_mixin.py:188} INFO - Đã tạo bảng thành công.
[2025-04-08T09:39:04.577+0000] {base.py:84} INFO - Using connection ID 'postgres_default' for task execution.
[2025-04-08T09:39:05.986+0000] {logging_mixin.py:188} INFO - Lỗi khi insert dữ liệu: invalid input syntax for type integer: "1:27.452"
LINE 3:         VALUES (18, 1, 2008, 1, '1', 10.0, '1:27.452', 1, 1,...
                                                   ^
[2025-04-08T09:39:05.987+0000] {taskinstance.py:441} INFO - ::group::Post task execution logs
[2025-04-08T09:39:05.988+0000] {taskinstance.py:2905} ERROR - Task failed with exception
Traceback (most recent call last):
  File "/home/airflow/.local/lib/python3.12/site-packages/airflow/models/taskinstance.py", line 465, in _execute_task
    result = _execute_callable(context=context, **execute_callable_kwargs)
             ^^^^^^^^^^^^^^^^^^^^^^^^^^^^^^^^^^^^^^^^^^^^^^^^^^^^^^^^^^^^^
  File "/home/airflow/.local/lib/python3.12/site-packages/airflow/models/taskinstance.py", line 432, in _execute_callable
    return execute_callable(context=context, **execute_callable_kwargs)
           ^^^^^^^^^^^^^^^^^^^^^^^^^^^^^^^^^^^^^^^^^^^^^^^^^^^^^^^^^^^^
  File "/home/airflow/.local/lib/python3.12/site-packages/airflow/models/baseoperator.py", line 401, in wrapper
    return func(self, *args, **kwargs)
           ^^^^^^^^^^^^^^^^^^^^^^^^^^^
  File "/home/airflow/.local/lib/python3.12/site-packages/airflow/operators/python.py", line 235, in execute
    return_value = self.execute_callable()
                   ^^^^^^^^^^^^^^^^^^^^^^^
  File "/home/airflow/.local/lib/python3.12/site-packages/airflow/operators/python.py", line 252, in execute_callable
    return self.python_callable(*self.op_args, **self.op_kwargs)
           ^^^^^^^^^^^^^^^^^^^^^^^^^^^^^^^^^^^^^^^^^^^^^^^^^^^^^
  File "/opt/airflow/dags/transform_fact_race_results.py", line 71, in transform_fact_race_results
    warehouse_operator.insert_table(insert_table_querry, fact_race_results__df)
  File "/opt/airflow/dags/postgresql_operator.py", line 35, in insert_table
    cursor.executemany(query, values)
psycopg2.errors.InvalidTextRepresentation: invalid input syntax for type integer: "1:27.452"
LINE 3:         VALUES (18, 1, 2008, 1, '1', 10.0, '1:27.452', 1, 1,...
                                                   ^

[2025-04-08T09:39:06.003+0000] {taskinstance.py:1206} INFO - Marking task as FAILED. dag_id=formula1-etl-pipeline, task_id=load.transform_fact_race_results, run_id=manual__2025-04-08T09:38:59.375674+00:00, execution_date=20250408T093859, start_date=20250408T093904, end_date=20250408T093906
[2025-04-08T09:39:06.017+0000] {standard_task_runner.py:110} ERROR - Failed to execute job 88 for task load.transform_fact_race_results (invalid input syntax for type integer: "1:27.452"
LINE 3:         VALUES (18, 1, 2008, 1, '1', 10.0, '1:27.452', 1, 1,...
                                                   ^
; 318)
[2025-04-08T09:39:06.069+0000] {local_task_job_runner.py:240} INFO - Task exited with return code 1
[2025-04-08T09:39:06.085+0000] {taskinstance.py:3503} INFO - 0 downstream tasks scheduled from follow-on schedule check
[2025-04-08T09:39:06.087+0000] {local_task_job_runner.py:222} INFO - ::endgroup::
