[2025-04-05T04:50:00.603+0000] {local_task_job_runner.py:120} INFO - ::group::Pre task execution logs
[2025-04-05T04:50:00.669+0000] {taskinstance.py:2076} INFO - Dependencies all met for dep_context=non-requeueable deps ti=<TaskInstance: e_commerce_dw_etl.transform.transform_dim_status scheduled__2025-04-01T00:00:00+00:00 [queued]>
[2025-04-05T04:50:00.690+0000] {taskinstance.py:2076} INFO - Dependencies all met for dep_context=requeueable deps ti=<TaskInstance: e_commerce_dw_etl.transform.transform_dim_status scheduled__2025-04-01T00:00:00+00:00 [queued]>
[2025-04-05T04:50:00.696+0000] {taskinstance.py:2306} INFO - Starting attempt 1 of 1
[2025-04-05T04:50:00.735+0000] {taskinstance.py:2330} INFO - Executing <Task(PythonOperator): transform.transform_dim_status> on 2025-04-01 00:00:00+00:00
[2025-04-05T04:50:00.768+0000] {standard_task_runner.py:90} INFO - Running: ['***', 'tasks', 'run', 'e_commerce_dw_etl', 'transform.transform_dim_status', 'scheduled__2025-04-01T00:00:00+00:00', '--job-id', '34', '--raw', '--subdir', 'DAGS_FOLDER/ETL_dag.py', '--cfg-path', '/tmp/tmppvfiq1td']
[2025-04-05T04:50:00.771+0000] {standard_task_runner.py:91} INFO - Job 34: Subtask transform.transform_dim_status
[2025-04-05T04:50:00.769+0000] {logging_mixin.py:188} WARNING - /home/***/.local/lib/python3.12/site-packages/***/task/task_runner/standard_task_runner.py:61 DeprecationWarning: This process (pid=452) is multi-threaded, use of fork() may lead to deadlocks in the child.
[2025-04-05T04:50:00.787+0000] {standard_task_runner.py:63} INFO - Started process 484 to run task
[2025-04-05T04:50:01.001+0000] {task_command.py:426} INFO - Running <TaskInstance: e_commerce_dw_etl.transform.transform_dim_status scheduled__2025-04-01T00:00:00+00:00 [running]> on host 7b82c2aa8826
[2025-04-05T04:50:01.338+0000] {taskinstance.py:2648} INFO - Exporting env vars: AIRFLOW_CTX_DAG_OWNER='***' AIRFLOW_CTX_DAG_ID='e_commerce_dw_etl' AIRFLOW_CTX_TASK_ID='transform.transform_dim_status' AIRFLOW_CTX_EXECUTION_DATE='2025-04-01T00:00:00+00:00' AIRFLOW_CTX_TRY_NUMBER='1' AIRFLOW_CTX_DAG_RUN_ID='scheduled__2025-04-01T00:00:00+00:00'
[2025-04-05T04:50:01.344+0000] {taskinstance.py:430} INFO - ::endgroup::
[2025-04-05T04:50:01.626+0000] {base.py:84} INFO - Using connection ID 'postgres_default' for task execution.
[2025-04-05T04:50:01.723+0000] {base.py:84} INFO - Using connection ID 'postgres_default' for task execution.
[2025-04-05T04:50:01.799+0000] {logging_mixin.py:188} INFO - Lỗi khi insert dữ liệu: duplicate key value violates unique constraint "dim_status_pkey"
DETAIL:  Key (statusid)=(1) already exists.
[2025-04-05T04:50:01.809+0000] {python.py:237} INFO - Done. Returned value was: None
[2025-04-05T04:50:01.812+0000] {taskinstance.py:441} INFO - ::group::Post task execution logs
[2025-04-05T04:50:01.855+0000] {taskinstance.py:1206} INFO - Marking task as SUCCESS. dag_id=e_commerce_dw_etl, task_id=transform.transform_dim_status, run_id=scheduled__2025-04-01T00:00:00+00:00, execution_date=20250401T000000, start_date=20250405T045000, end_date=20250405T045001
[2025-04-05T04:50:01.985+0000] {local_task_job_runner.py:240} INFO - Task exited with return code 0
[2025-04-05T04:50:02.048+0000] {taskinstance.py:3503} INFO - 0 downstream tasks scheduled from follow-on schedule check
[2025-04-05T04:50:02.056+0000] {local_task_job_runner.py:222} INFO - ::endgroup::
[2025-04-05T04:54:06.476+0000] {local_task_job_runner.py:120} INFO - ::group::Pre task execution logs
[2025-04-05T04:54:06.571+0000] {taskinstance.py:2076} INFO - Dependencies all met for dep_context=non-requeueable deps ti=<TaskInstance: e_commerce_dw_etl.transform.transform_dim_status scheduled__2025-04-01T00:00:00+00:00 [queued]>
[2025-04-05T04:54:06.587+0000] {taskinstance.py:2076} INFO - Dependencies all met for dep_context=requeueable deps ti=<TaskInstance: e_commerce_dw_etl.transform.transform_dim_status scheduled__2025-04-01T00:00:00+00:00 [queued]>
[2025-04-05T04:54:06.590+0000] {taskinstance.py:2306} INFO - Starting attempt 1 of 1
[2025-04-05T04:54:06.629+0000] {taskinstance.py:2330} INFO - Executing <Task(PythonOperator): transform.transform_dim_status> on 2025-04-01 00:00:00+00:00
[2025-04-05T04:54:06.657+0000] {logging_mixin.py:188} WARNING - /home/***/.local/lib/python3.12/site-packages/***/task/task_runner/standard_task_runner.py:61 DeprecationWarning: This process (pid=431) is multi-threaded, use of fork() may lead to deadlocks in the child.
[2025-04-05T04:54:06.661+0000] {standard_task_runner.py:63} INFO - Started process 486 to run task
[2025-04-05T04:54:06.658+0000] {standard_task_runner.py:90} INFO - Running: ['***', 'tasks', 'run', 'e_commerce_dw_etl', 'transform.transform_dim_status', 'scheduled__2025-04-01T00:00:00+00:00', '--job-id', '43', '--raw', '--subdir', 'DAGS_FOLDER/ETL_dag.py', '--cfg-path', '/tmp/tmpadbel91k']
[2025-04-05T04:54:06.672+0000] {standard_task_runner.py:91} INFO - Job 43: Subtask transform.transform_dim_status
[2025-04-05T04:54:06.837+0000] {task_command.py:426} INFO - Running <TaskInstance: e_commerce_dw_etl.transform.transform_dim_status scheduled__2025-04-01T00:00:00+00:00 [running]> on host 4766eee3ca7d
[2025-04-05T04:54:07.198+0000] {taskinstance.py:2648} INFO - Exporting env vars: AIRFLOW_CTX_DAG_OWNER='***' AIRFLOW_CTX_DAG_ID='e_commerce_dw_etl' AIRFLOW_CTX_TASK_ID='transform.transform_dim_status' AIRFLOW_CTX_EXECUTION_DATE='2025-04-01T00:00:00+00:00' AIRFLOW_CTX_TRY_NUMBER='1' AIRFLOW_CTX_DAG_RUN_ID='scheduled__2025-04-01T00:00:00+00:00'
[2025-04-05T04:54:07.217+0000] {taskinstance.py:430} INFO - ::endgroup::
[2025-04-05T04:54:07.383+0000] {taskinstance.py:441} INFO - ::group::Post task execution logs
[2025-04-05T04:54:07.467+0000] {taskinstance.py:2905} ERROR - Task failed with exception
Traceback (most recent call last):
  File "/home/airflow/.local/lib/python3.12/site-packages/airflow/models/taskinstance.py", line 465, in _execute_task
    result = _execute_callable(context=context, **execute_callable_kwargs)
             ^^^^^^^^^^^^^^^^^^^^^^^^^^^^^^^^^^^^^^^^^^^^^^^^^^^^^^^^^^^^^
  File "/home/airflow/.local/lib/python3.12/site-packages/airflow/models/taskinstance.py", line 432, in _execute_callable
    return execute_callable(context=context, **execute_callable_kwargs)
           ^^^^^^^^^^^^^^^^^^^^^^^^^^^^^^^^^^^^^^^^^^^^^^^^^^^^^^^^^^^^
  File "/home/airflow/.local/lib/python3.12/site-packages/airflow/models/baseoperator.py", line 401, in wrapper
    return func(self, *args, **kwargs)
           ^^^^^^^^^^^^^^^^^^^^^^^^^^^
  File "/home/airflow/.local/lib/python3.12/site-packages/airflow/operators/python.py", line 235, in execute
    return_value = self.execute_callable()
                   ^^^^^^^^^^^^^^^^^^^^^^^
  File "/home/airflow/.local/lib/python3.12/site-packages/airflow/operators/python.py", line 252, in execute_callable
    return self.python_callable(*self.op_args, **self.op_kwargs)
           ^^^^^^^^^^^^^^^^^^^^^^^^^^^^^^^^^^^^^^^^^^^^^^^^^^^^^
  File "/opt/airflow/dags/transform_dim_status.py", line 26, in transform_dim_status
    warehouse_operator.create_table(create_table_qr)
  File "/opt/airflow/dags/postgresql_operator.py", line 10, in create_table
    conn = pg_hook.get_conn()
           ^^^^^^^^^^^^^^^^^^
  File "/home/airflow/.local/lib/python3.12/site-packages/airflow/providers/postgres/hooks/postgres.py", line 145, in get_conn
    conn = deepcopy(self.connection or self.get_connection(conn_id))
                                       ^^^^^^^^^^^^^^^^^^^^^^^^^^^^
  File "/home/airflow/.local/lib/python3.12/site-packages/airflow/hooks/base.py", line 83, in get_connection
    conn = Connection.get_connection_from_secrets(conn_id)
           ^^^^^^^^^^^^^^^^^^^^^^^^^^^^^^^^^^^^^^^^^^^^^^^
  File "/home/airflow/.local/lib/python3.12/site-packages/airflow/models/connection.py", line 519, in get_connection_from_secrets
    raise AirflowNotFoundException(f"The conn_id `{conn_id}` isn't defined")
airflow.exceptions.AirflowNotFoundException: The conn_id `postgres_default` isn't defined
[2025-04-05T04:54:07.509+0000] {taskinstance.py:1206} INFO - Marking task as FAILED. dag_id=e_commerce_dw_etl, task_id=transform.transform_dim_status, run_id=scheduled__2025-04-01T00:00:00+00:00, execution_date=20250401T000000, start_date=20250405T045406, end_date=20250405T045407
[2025-04-05T04:54:07.575+0000] {standard_task_runner.py:110} ERROR - Failed to execute job 43 for task transform.transform_dim_status (The conn_id `postgres_default` isn't defined; 486)
[2025-04-05T04:54:07.641+0000] {local_task_job_runner.py:240} INFO - Task exited with return code 1
[2025-04-05T04:54:07.674+0000] {taskinstance.py:3503} INFO - 0 downstream tasks scheduled from follow-on schedule check
[2025-04-05T04:54:07.678+0000] {local_task_job_runner.py:222} INFO - ::endgroup::
