[2025-04-03T14:26:03.382+0000] {local_task_job_runner.py:120} INFO - ::group::Pre task execution logs
[2025-04-03T14:26:03.409+0000] {taskinstance.py:2076} INFO - Dependencies all met for dep_context=non-requeueable deps ti=<TaskInstance: e_commerce_dw_etl.transform.transform_dim_circuits manual__2025-04-03T14:26:02.415223+00:00 [queued]>
[2025-04-03T14:26:03.417+0000] {taskinstance.py:2076} INFO - Dependencies all met for dep_context=requeueable deps ti=<TaskInstance: e_commerce_dw_etl.transform.transform_dim_circuits manual__2025-04-03T14:26:02.415223+00:00 [queued]>
[2025-04-03T14:26:03.418+0000] {taskinstance.py:2306} INFO - Starting attempt 1 of 1
[2025-04-03T14:26:03.430+0000] {taskinstance.py:2330} INFO - Executing <Task(PythonOperator): transform.transform_dim_circuits> on 2025-04-03 14:26:02.415223+00:00
[2025-04-03T14:26:03.439+0000] {standard_task_runner.py:90} INFO - Running: ['***', 'tasks', 'run', 'e_commerce_dw_etl', 'transform.transform_dim_circuits', 'manual__2025-04-03T14:26:02.415223+00:00', '--job-id', '79', '--raw', '--subdir', 'DAGS_FOLDER/ETL_dag.py', '--cfg-path', '/tmp/tmpbcq2o0__']
[2025-04-03T14:26:03.441+0000] {standard_task_runner.py:91} INFO - Job 79: Subtask transform.transform_dim_circuits
[2025-04-03T14:26:03.442+0000] {logging_mixin.py:188} WARNING - /home/***/.local/lib/python3.12/site-packages/***/task/task_runner/standard_task_runner.py:61 DeprecationWarning: This process (pid=235) is multi-threaded, use of fork() may lead to deadlocks in the child.
[2025-04-03T14:26:03.443+0000] {standard_task_runner.py:63} INFO - Started process 239 to run task
[2025-04-03T14:26:03.482+0000] {task_command.py:426} INFO - Running <TaskInstance: e_commerce_dw_etl.transform.transform_dim_circuits manual__2025-04-03T14:26:02.415223+00:00 [running]> on host c54a961f128a
[2025-04-03T14:26:03.560+0000] {taskinstance.py:2648} INFO - Exporting env vars: AIRFLOW_CTX_DAG_OWNER='***' AIRFLOW_CTX_DAG_ID='e_commerce_dw_etl' AIRFLOW_CTX_TASK_ID='transform.transform_dim_circuits' AIRFLOW_CTX_EXECUTION_DATE='2025-04-03T14:26:02.415223+00:00' AIRFLOW_CTX_TRY_NUMBER='1' AIRFLOW_CTX_DAG_RUN_ID='manual__2025-04-03T14:26:02.415223+00:00'
[2025-04-03T14:26:03.561+0000] {taskinstance.py:430} INFO - ::endgroup::
[2025-04-03T14:26:03.575+0000] {logging_mixin.py:188} INFO - /opt/***/dataset
[2025-04-03T14:26:03.584+0000] {logging_mixin.py:188} INFO - đã đọc được circuits
[2025-04-03T14:26:03.587+0000] {logging_mixin.py:188} INFO - tạo dc postgres
[2025-04-03T14:26:03.596+0000] {base.py:84} INFO - Using connection ID 'postgres_default' for task execution.
[2025-04-03T14:26:03.599+0000] {taskinstance.py:441} INFO - ::group::Post task execution logs
[2025-04-03T14:26:03.600+0000] {taskinstance.py:2905} ERROR - Task failed with exception
Traceback (most recent call last):
  File "/home/airflow/.local/lib/python3.12/site-packages/airflow/models/taskinstance.py", line 465, in _execute_task
    result = _execute_callable(context=context, **execute_callable_kwargs)
             ^^^^^^^^^^^^^^^^^^^^^^^^^^^^^^^^^^^^^^^^^^^^^^^^^^^^^^^^^^^^^
  File "/home/airflow/.local/lib/python3.12/site-packages/airflow/models/taskinstance.py", line 432, in _execute_callable
    return execute_callable(context=context, **execute_callable_kwargs)
           ^^^^^^^^^^^^^^^^^^^^^^^^^^^^^^^^^^^^^^^^^^^^^^^^^^^^^^^^^^^^
  File "/home/airflow/.local/lib/python3.12/site-packages/airflow/models/baseoperator.py", line 401, in wrapper
    return func(self, *args, **kwargs)
           ^^^^^^^^^^^^^^^^^^^^^^^^^^^
  File "/home/airflow/.local/lib/python3.12/site-packages/airflow/operators/python.py", line 235, in execute
    return_value = self.execute_callable()
                   ^^^^^^^^^^^^^^^^^^^^^^^
  File "/home/airflow/.local/lib/python3.12/site-packages/airflow/operators/python.py", line 252, in execute_callable
    return self.python_callable(*self.op_args, **self.op_kwargs)
           ^^^^^^^^^^^^^^^^^^^^^^^^^^^^^^^^^^^^^^^^^^^^^^^^^^^^^
  File "/opt/airflow/dags/transform_dim_circuits.py", line 35, in transform_dim_circuits
    warehouse_operator.create_table(create_table_qr)
  File "/opt/airflow/dags/postgresql_operator.py", line 12, in create_table
    conn = pg_hook.get_conn()
           ^^^^^^^^^^^^^^^^^^
  File "/home/airflow/.local/lib/python3.12/site-packages/airflow/providers/postgres/hooks/postgres.py", line 175, in get_conn
    self.conn = psycopg2.connect(**conn_args)
                ^^^^^^^^^^^^^^^^^^^^^^^^^^^^^
  File "/home/airflow/.local/lib/python3.12/site-packages/psycopg2/__init__.py", line 122, in connect
    conn = _connect(dsn, connection_factory=connection_factory, **kwasync)
           ^^^^^^^^^^^^^^^^^^^^^^^^^^^^^^^^^^^^^^^^^^^^^^^^^^^^^^^^^^^^^^^
psycopg2.OperationalError: connection to server at "postgres_db" (172.18.0.3), port 5433 failed: FATAL:  role "root" does not exist

[2025-04-03T14:26:03.614+0000] {taskinstance.py:1206} INFO - Marking task as FAILED. dag_id=e_commerce_dw_etl, task_id=transform.transform_dim_circuits, run_id=manual__2025-04-03T14:26:02.415223+00:00, execution_date=20250403T142602, start_date=20250403T142603, end_date=20250403T142603
[2025-04-03T14:26:03.624+0000] {standard_task_runner.py:110} ERROR - Failed to execute job 79 for task transform.transform_dim_circuits (connection to server at "postgres_db" (172.18.0.3), port 5433 failed: FATAL:  role "root" does not exist
; 239)
[2025-04-03T14:26:03.657+0000] {local_task_job_runner.py:240} INFO - Task exited with return code 1
[2025-04-03T14:26:03.675+0000] {taskinstance.py:3503} INFO - 0 downstream tasks scheduled from follow-on schedule check
[2025-04-03T14:26:03.676+0000] {local_task_job_runner.py:222} INFO - ::endgroup::
